import UIKit
/*
 错误处理（Error handling） 是响应错误以及从错误中恢复的过程。Swift 在运行时提供了抛出、捕获、传递和操作可恢复错误（recoverable errors）的一等支持（first-class support）。
 表示与抛出错误
 
 处理错误
   用throwing函数传递错误
   用do-catch处理错误
   将错误转换成可选值 ？
   禁用错误传递 ！
 指定清理操作
 */
enum VendingMachineError: Error {
    case invalidSelection
    case insufficientFunds(coinsNeeded: Int)
    case outOfStock
}
throw VendingMachineError.insufficientFunds(coinsNeeded: 5)

//func canThrowErrors() throws -> String

struct Item {
    var price: Int
    var count: Int
}
class VendingMachine {
    var inventory = [
        "Candy Bar": Item(price: 12, count: 7),
        "Chips": Item(price: 10, count: 4),
        "Pretzels": Item(price: 7, count: 11)
    ]
    
    var coinsDeposited = 0
    
    func vend(itemNamed name: String) throws {
        guard let item = inventory[name] else {
            throw VendingMachineError.invalidSelection
        }
        
        guard item.count > 0 else {
            throw VendingMachineError.outOfStock
        }
        
        guard item.price <= coinsDeposited else {
            throw VendingMachineError.insufficientFunds(coinsNeeded: item.price)
        }
        
        coinsDeposited -= item.price
        
        var newItem = item
        newItem.count -= 1
        inventory[name] = newItem
        print("Dispensing \(name)")
    }
}

let favoriteSnacks = [
    "Alice": "Chips",
    "Bob": "Licorice",
    "Eve": "Pretzels",
]

func buyFavoriteSnack(person: String, vendingMachine: VendingMachine) throws {
    let snackName = favoriteSnacks[person] ?? "Candy Bar"
    try vendingMachine.vend(itemNamed: snackName)
}

struct PurchasedSnack {
    let name: String
    init(name: String, vendingMachine: VendingMachine) throws {
        try vendingMachine.vend(itemNamed: name)
        self.name = name
    }
}

var vendingMachine = VendingMachine()
vendingMachine.coinsDeposited = 8
do {
    try buyFavoriteSnack(person: "Alice", vendingMachine: vendingMachine)
    print("Success! Yum.")
} catch VendingMachineError.invalidSelection {
    print("Invalid Selection")
} catch {
    print("Unexpected error: \(error).")
}


func nourish(with item: String) throws {
    do {
        try vendingMachine.vend(itemNamed: item)
    } catch is VendingMachineError {
        print("Invalid selection, out of stock, or not enough money")
    }
}

do {
    try nourish(with: "Beet-Flavored Chips")
} catch {
    print("Unexpected non-vending-machine-related error: \(error)")
}

func someThrowingFunction() throws -> Int {
    return 1
}

let x = try? someThrowingFunction()

let y: Int?
do {
   y = try someThrowingFunction()
} catch  {
   y = nil
}

//func fetchData() -> Data? {
//    if let data = try? fetchDataFromDisk(){return data}
//    if let data = try? fetchDataFromDisk(){return data}
//    return nil
//}

//let photo = try! loadImage(atPath: "./Resources/John Appleseed.jpg")
/*
 你可以使用 defer 语句在即将离开当前代码块时执行一系列语句。该语句让你能执行一些必要的清理工作，不管是以何种方式离开当前代码块的——无论是由于抛出错误而离开，或是由于诸如 return、break 的语句。例如，你可以用 defer 语句来确保文件描述符得以关闭，以及手动分配的内存得以释放。
 
func processFile(filename: String) throws {
    if exists(filename) {
        let file = open(filename)
        defer {
            close(file)
        }
        while let line = try file.readline() {
            // 处理文件
        }
        // close(file) 会在这里被调用，即作用域的最后
    }
}
 
 注意

 即使没有涉及到错误处理的代码，你也可以使用 defer 语句。
*/
